<?xml version="1.0" ?>
<!-- =================================================================================== -->
<!-- |    This document was autogenerated by xacro from panda_mounted_husky.urdf.xacro | -->
<!-- |    EDITING THIS FILE BY HAND IS NOT RECOMMENDED                                 | -->
<!-- =================================================================================== -->
<robot name="panda_mounted_husky">
  <!-- Tune the mount offset as you like -->
  <!-- <xacro:arg name="mount_xyz" default="0 0 0.2325"/>
  <xacro:arg name="mount_rpy" default="0 0 0"/> -->
  <!-- =========================
          LINKS
          ========================= -->
  <!-- base_link -->
  <link name="base_link">
    <inertial>
      <origin rpy="0 0 0" xyz="-0.000543 -0.084945 0.062329"/>
      <mass value="46.064"/>
      <inertia ixx="0.615397" ixy="-0.0240585" ixz="-0.120749" iyy="1.75388" iyz="-0.0028322" izz="2.03641"/>
    </inertial>
    <!-- <joint name="base_footprint_joint" type="fixed">
            <parent link="base_link"/>
            <child link="base_footprint"/>
            <origin xyz="0 0 0" rpy="0 0 0"/>
        </joint>

        <link name="base_footprint">
        </link> -->
    <!-- Collisions -->
    <collision name="base_link_collision">
      <origin rpy="0 0 0" xyz="0 0 0.12"/>
      <geometry>
        <box size="0.9874 0.5709 0.05"/>
      </geometry>
    </collision>
    <collision name="base_link_collision_bottom">
      <origin rpy="0 0 0" xyz="0 0 0.046"/>
      <geometry>
        <box size="0.80 0.5709 0.095"/>
      </geometry>
    </collision>
    <collision name="base_link_collision_1">
      <origin rpy="0 0 0" xyz="0 0 0.185625"/>
      <geometry>
        <box size="0.78992 0.5709 0.12375"/>
      </geometry>
    </collision>
    <collision name="sensor_tower_collision">
      <origin rpy="0 0 0" xyz="0.374 0 0.215"/>
      <geometry>
        <box size="0.2 0.25 0.225"/>
      </geometry>
    </collision>
    <collision name="landing_pad_collision">
      <origin rpy="0 0 0" xyz="0.0 0 0.155"/>
      <geometry>
        <box size="0.500 0.385 0.155"/>
      </geometry>
    </collision>
    <!-- Visuals -->
    <visual name="base_link_visual">
      <origin rpy="0 0 0" xyz="0 0 0"/>
      <geometry>
        <mesh filename="package://husky_panda_description/husky_panda_model/panda_mounted_husky/husky_robot_description/meshes/base_link.dae" scale="1 1 1"/>
      </geometry>
    </visual>
    <!-- <visual name="front_bumper_visual">
      <origin rpy="0 0 0" xyz="0.48 0 0.091"/>
      <geometry>
        <mesh filename="package://husky_panda_description/husky_panda_model/panda_mounted_husky/husky_robot_description/meshes/bumper.dae"/>
      </geometry>
    </visual> -->
    <!-- <visual name="rear_bumper_visual">
      <origin rpy="0 0 3.14159" xyz="-0.48 0 0.091"/>
      <geometry>
        <mesh filename="package://husky_panda_description/husky_panda_model/panda_mounted_husky/husky_robot_description/meshes/bumper.dae"/>
      </geometry>
    </visual> -->
    <visual name="top_chassis_visual">
      <origin rpy="0 0 0" xyz="0 0 0"/>
      <geometry>
        <mesh filename="package://husky_panda_description/husky_panda_model/panda_mounted_husky/husky_robot_description/meshes/top_chassis.dae"/>
      </geometry>
    </visual>
    <visual name="velodyne_base_visual_1">
      <origin rpy="0 0 0" xyz="0.424 0 0.327"/>
      <geometry>
        <mesh filename="package://husky_panda_description/husky_panda_model/panda_mounted_husky/husky_robot_description/meshes/VLP16_base_1.dae"/>
      </geometry>
    </visual>
    <visual name="velodyne_base_visual_2">
      <origin rpy="0 0 0" xyz="0.424 0 0.327"/>
      <geometry>
        <mesh filename="package://husky_panda_description/husky_panda_model/panda_mounted_husky/husky_robot_description/meshes/VLP16_base_2.dae"/>
      </geometry>
    </visual>
    <visual name="velodyne_scan_visual">
      <origin rpy="0 0 0" xyz="0.424 0 0.327"/>
      <geometry>
        <mesh filename="package://husky_panda_description/husky_panda_model/panda_mounted_husky/husky_robot_description/meshes/VLP16_scan.dae"/>
      </geometry>
    </visual>
    <visual name="user_rail_visual">
      <origin rpy="0 0 0" xyz="0.272 0 0.245"/>
      <geometry>
        <mesh filename="package://husky_panda_description/husky_panda_model/panda_mounted_husky/husky_robot_description/meshes/user_rail.dae"/>
      </geometry>
    </visual>
    <visual name="planar_lidar_visual">
      <origin rpy="0 0 0" xyz="0.474 0 0.127"/>
      <geometry>
        <cylinder length="0.05" radius="0.045"/>
      </geometry>
    </visual>
    <visual name="sensor_tower_visual">
      <origin rpy="0 0 0" xyz="0.374 0 0.215"/>
      <geometry>
        <box size="0.2 0.25 0.225"/>
      </geometry>
    </visual>
    <visual name="landing_pad_visual">
      <origin rpy="0 0 0" xyz="0.0 0 0.155"/>
      <geometry>
        <box size="0.500 0.385 0.155"/>
      </geometry>
    </visual>
    <visual name="base_realsense_down_visual">
      <origin rpy="0 -0.035 0" xyz="0.478 0 0.260"/>
      <geometry>
        <mesh filename="package://husky_panda_description/husky_panda_model/panda_mounted_husky/husky_robot_description/meshes/realsense.dae"/>
      </geometry>
    </visual>
    <visual name="base_realsense_front_visual">
      <origin rpy="0 0 0" xyz="0.478 0 0.285"/>
      <geometry>
        <mesh filename="package://husky_panda_description/husky_panda_model/panda_mounted_husky/husky_robot_description/meshes/realsense.dae"/>
      </geometry>
    </visual>
  </link>
  <!-- front_left_wheel_link -->
  <link name="front_left_wheel_link">
    <inertial>
      <origin xyz="0 0 0"/>
      <mass value="2.637"/>
      <inertia ixx="0.02467" ixy="0" ixz="0" iyy="0.04411" iyz="0" izz="0.02467"/>
    </inertial>
    <collision>
      <origin rpy="1.5707963267948966 0 0" xyz="0 0 0"/>
      <geometry>
        <cylinder length="0.1143" radius="0.1651"/>
      </geometry>
    </collision>
    <visual>
      <geometry>
        <mesh filename="package://husky_panda_description/husky_panda_model/panda_mounted_husky/husky_robot_description/meshes/wheel.dae"/>
      </geometry>
    </visual>
  </link>
  <!-- front_right_wheel_link -->
  <link name="front_right_wheel_link">
    <inertial>
      <origin xyz="0 0 0"/>
      <mass value="2.637"/>
      <inertia ixx="0.02467" ixy="0" ixz="0" iyy="0.04411" iyz="0" izz="0.02467"/>
    </inertial>
    <collision>
      <origin rpy="1.5707963267948966 0 0" xyz="0 0 0"/>
      <geometry>
        <cylinder length="0.1143" radius="0.1651"/>
      </geometry>
    </collision>
    <visual>
      <geometry>
        <mesh filename="package://husky_panda_description/husky_panda_model/panda_mounted_husky/husky_robot_description/meshes/wheel.dae"/>
      </geometry>
    </visual>
  </link>
  <!-- rear_left_wheel_link -->
  <link name="rear_left_wheel_link">
    <inertial>
      <origin xyz="0 0 0"/>
      <mass value="2.637"/>
      <inertia ixx="0.02467" ixy="0" ixz="0" iyy="0.04411" iyz="0" izz="0.02467"/>
    </inertial>
    <collision>
      <origin rpy="1.5707963267948966 0 0" xyz="0 0 0"/>
      <geometry>
        <cylinder length="0.1143" radius="0.1651"/>
      </geometry>
    </collision>
    <visual>
      <geometry>
        <mesh filename="package://husky_panda_description/husky_panda_model/panda_mounted_husky/husky_robot_description/meshes/wheel.dae"/>
      </geometry>
    </visual>
  </link>
  <!-- rear_right_wheel_link -->
  <link name="rear_right_wheel_link">
    <inertial>
      <origin xyz="0 0 0"/>
      <mass value="2.637"/>
      <inertia ixx="0.02467" ixy="0" ixz="0" iyy="0.04411" iyz="0" izz="0.02467"/>
    </inertial>
    <collision>
      <origin rpy="1.5707963267948966 0 0" xyz="0 0 0"/>
      <geometry>
        <cylinder length="0.1143" radius="0.1651"/>
      </geometry>
    </collision>
    <visual>
      <geometry>
        <mesh filename="package://husky_panda_description/husky_panda_model/panda_mounted_husky/husky_robot_description/meshes/wheel.dae"/>
      </geometry>
    </visual>
  </link>
  <!-- pan_gimbal_link -->
  <link name="pan_gimbal_link">
    <inertial>
      <origin xyz="0 0 0"/>
      <mass value="0.1"/>
      <inertia ixx="0.000016875" ixy="0" ixz="0" iyy="1e-8" iyz="0" izz="0.000016875"/>
    </inertial>
    <collision>
      <geometry>
        <cylinder length="0.045" radius="0.014"/>
      </geometry>
    </collision>
    <visual>
      <geometry>
        <cylinder length="0.045" radius="0.014"/>
      </geometry>
    </visual>
  </link>
  <!-- tilt_gimbal_link -->
  <link name="tilt_gimbal_link">
    <inertial>
      <origin rpy="1.570796 0 0" xyz="0 0 0"/>
      <mass value="0.1"/>
      <inertia ixx="0.000016875" ixy="0" ixz="0" iyy="1e-8" iyz="0" izz="0.000016875"/>
    </inertial>
    <collision>
      <origin rpy="1.570796 0 0"/>
      <geometry>
        <cylinder length="0.045" radius="0.014"/>
      </geometry>
    </collision>
    <visual>
      <origin rpy="1.570796 0 0"/>
      <geometry>
        <cylinder length="0.045" radius="0.014"/>
      </geometry>
    </visual>
    <!-- Extra visuals on tilt gimbal -->
    <visual name="tilt_realsense_visual">
      <origin rpy="0 0 0" xyz="0.0 0 0.03"/>
      <geometry>
        <mesh filename="package://husky_panda_description/husky_panda_model/panda_mounted_husky/husky_robot_description/meshes/realsense.dae"/>
      </geometry>
    </visual>
    <visual name="bot_camera_plate_low">
      <origin xyz="0 0 0.017"/>
      <geometry>
        <box size="0.025 0.13 0.007"/>
      </geometry>
    </visual>
    <visual name="bot_camera_plate_high">
      <origin xyz="0 0 0.042"/>
      <geometry>
        <box size="0.025 0.13 0.007"/>
      </geometry>
    </visual>
  </link>
  <!-- planar_lidar_link -->
  <link name="planar_lidar_link"/>
  <!-- =========================
          JOINTS
          ========================= -->
  <joint name="front_left_wheel_joint" type="continuous">
    <parent link="base_link"/>
    <child link="front_left_wheel_link"/>
    <origin rpy="0 0 0" xyz="0.256 0.2854 0.03282"/>
    <axis xyz="0 1 0"/>
  </joint>
  <joint name="front_right_wheel_joint" type="continuous">
    <parent link="base_link"/>
    <child link="front_right_wheel_link"/>
    <origin rpy="0 0 0" xyz="0.256 -0.2854 0.03282"/>
    <axis xyz="0 1 0"/>
  </joint>
  <joint name="rear_left_wheel_joint" type="continuous">
    <parent link="base_link"/>
    <child link="rear_left_wheel_link"/>
    <origin rpy="0 0 0" xyz="-0.256 0.2854 0.03282"/>
    <axis xyz="0 1 0"/>
  </joint>
  <joint name="rear_right_wheel_joint" type="continuous">
    <parent link="base_link"/>
    <child link="rear_right_wheel_link"/>
    <origin rpy="0 0 0" xyz="-0.256 -0.2854 0.03282"/>
    <axis xyz="0 1 0"/>
  </joint>
  <joint name="pan_gimbal_joint" type="continuous">
    <parent link="base_link"/>
    <child link="pan_gimbal_link"/>
    <origin rpy="0 0 0" xyz="0.424 0 0.427"/>
    <axis xyz="0 0 1"/>
  </joint>
  <joint name="tilt_gimbal_joint" type="revolute">
    <parent link="pan_gimbal_link"/>
    <child link="tilt_gimbal_link"/>
    <origin rpy="0 0 0" xyz="0 0 0.033"/>
    <axis xyz="0 1 0"/>
    <limit effort="10" lower="-1.5708" upper="1.5708" velocity="10"/>
  </joint>
  <!-- =========================
          GAZEBO / IGNITION
          ========================= -->
  <!-- Sensors mounted on base_link -->
  <gazebo reference="base_link">
    <!-- camera_front -->
    <sensor name="camera_front" type="rgbd_camera">
      <topic>camera_front</topic>
      <pose>0.468 0 0.360 0 0 0</pose>
      <update_rate>30</update_rate>
      <camera name="camera_front">
        <horizontal_fov>1.5184</horizontal_fov>
        <lens>
          <intrinsics>
            <fx>168.61097</fx>
            <fy>168.61097</fy>
            <cx>160.5</cx>
            <cy>120.5</cy>
            <s>0</s>
          </intrinsics>
        </lens>
        <distortion>
          <k1>0</k1>
          <k2>0</k2>
          <k3>0</k3>
          <p1>0</p1>
          <p2>0</p2>
          <center>0.5 0.5</center>
        </distortion>
        <image>
          <width>320</width>
          <height>240</height>
          <format>R8G8B8</format>
        </image>
        <clip>
          <near>0.01</near>
          <far>300</far>
        </clip>
        <depth_camera>
          <clip>
            <near>0.1</near>
            <far>10</far>
          </clip>
        </depth_camera>
        <noise>
          <type>gaussian</type>
          <mean>0</mean>
          <stddev>0.007</stddev>
        </noise>
      </camera>
    </sensor>
    <!-- camera_down -->
    <sensor name="camera_down" type="rgbd_camera">
      <topic>camera_down</topic>
      <pose>0.468 0 0.335 0 0.5236 0</pose>
      <update_rate>30</update_rate>
      <camera name="camera_down">
        <horizontal_fov>1.5184</horizontal_fov>
        <lens>
          <intrinsics>
            <fx>168.61097</fx>
            <fy>168.61097</fy>
            <cx>160.5</cx>
            <cy>120.5</cy>
            <s>0</s>
          </intrinsics>
        </lens>
        <distortion>
          <k1>0</k1>
          <k2>0</k2>
          <k3>0</k3>
          <p1>0</p1>
          <p2>0</p2>
          <center>0.5 0.5</center>
        </distortion>
        <image>
          <width>320</width>
          <height>240</height>
          <format>R8G8B8</format>
        </image>
        <clip>
          <near>0.01</near>
          <far>300</far>
        </clip>
        <depth_camera>
          <clip>
            <near>0.1</near>
            <far>10</far>
          </clip>
        </depth_camera>
        <noise>
          <type>gaussian</type>
          <mean>0</mean>
          <stddev>0.007</stddev>
        </noise>
      </camera>
    </sensor>
    <!-- planar 2D lidar -->
    <sensor name="planar_laser" type="gpu_ray">
      <topic>planar_laser</topic>
      <pose>0.474 0 0.127 0 0 0</pose>
      <update_rate>10</update_rate>
      <lidar>
        <scan>
          <horizontal>
            <samples>360</samples>
            <resolution>1</resolution>
            <min_angle>-3.14159</min_angle>
            <max_angle>3.14159</max_angle>
          </horizontal>
        </scan>
        <range>
          <min>0.05</min>
          <max>12</max>
          <resolution>0.01</resolution>
        </range>
        <noise>
          <type>gaussian</type>
          <mean>0</mean>
          <stddev>0.01</stddev>
        </noise>
      </lidar>
    </sensor>
    <!-- front 3D lidar -->
    <sensor name="front_laser" type="gpu_lidar">
      <topic>front_laser</topic>
      <pose>0.424 0 0.387 0 0 0</pose>
      <update_rate>20</update_rate>
      <lidar>
        <scan>
          <horizontal>
            <samples>1024</samples>
            <resolution>1</resolution>
            <min_angle>-3.14159</min_angle>
            <max_angle>3.14159</max_angle>
          </horizontal>
          <vertical>
            <samples>64</samples>
            <resolution>1</resolution>
            <min_angle>-0.2897</min_angle>
            <max_angle>0.2897</max_angle>
          </vertical>
        </scan>
        <range>
          <min>0.8</min>
          <max>120</max>
          <resolution>0.003</resolution>
        </range>
        <noise>
          <type>gaussian</type>
          <mean>0</mean>
          <stddev>0.03</stddev>
        </noise>
      </lidar>
    </sensor>
    <!-- IMU -->
    <sensor name="imu_sensor" type="imu">
      <topic>/imu_sensor</topic>
      <pose>0 0 0 0 0 0</pose>
      <update_rate>50</update_rate>
      <imu>
        <angular_velocity>
          <x>
            <noise type="gaussian">
              <mean>0</mean>
              <stddev>0.009</stddev>
              <bias_mean>0.00075</bias_mean>
              <bias_stddev>0.005</bias_stddev>
              <dynamic_bias_stddev>0.00002</dynamic_bias_stddev>
              <dynamic_bias_correlation_time>400.0</dynamic_bias_correlation_time>
              <precision>0.00025</precision>
            </noise>
          </x>
          <y>
            <noise type="gaussian">
              <mean>0</mean>
              <stddev>0.009</stddev>
              <bias_mean>0.00075</bias_mean>
              <bias_stddev>0.005</bias_stddev>
              <dynamic_bias_stddev>0.00002</dynamic_bias_stddev>
              <dynamic_bias_correlation_time>400.0</dynamic_bias_correlation_time>
              <precision>0.00025</precision>
            </noise>
          </y>
          <z>
            <noise type="gaussian">
              <mean>0</mean>
              <stddev>0.009</stddev>
              <bias_mean>0.00075</bias_mean>
              <bias_stddev>0.005</bias_stddev>
              <dynamic_bias_stddev>0.00002</dynamic_bias_stddev>
              <dynamic_bias_correlation_time>400.0</dynamic_bias_correlation_time>
              <precision>0.00025</precision>
            </noise>
          </z>
        </angular_velocity>
        <linear_acceleration>
          <x>
            <noise type="gaussian">
              <mean>0</mean>
              <stddev>0.021</stddev>
              <bias_mean>0.05</bias_mean>
              <bias_stddev>0.0075</bias_stddev>
              <dynamic_bias_stddev>0.000375</dynamic_bias_stddev>
              <dynamic_bias_correlation_time>175.0</dynamic_bias_correlation_time>
              <precision>0.005</precision>
            </noise>
          </x>
          <y>
            <noise type="gaussian">
              <mean>0</mean>
              <stddev>0.021</stddev>
              <bias_mean>0.05</bias_mean>
              <bias_stddev>0.0075</bias_stddev>
              <dynamic_bias_stddev>0.000375</dynamic_bias_stddev>
              <dynamic_bias_correlation_time>175.0</dynamic_bias_correlation_time>
              <precision>0.005</precision>
            </noise>
          </y>
          <z>
            <noise type="gaussian">
              <mean>0</mean>
              <stddev>0.021</stddev>
              <bias_mean>0.05</bias_mean>
              <bias_stddev>0.0075</bias_stddev>
              <dynamic_bias_stddev>0.000375</dynamic_bias_stddev>
              <dynamic_bias_correlation_time>175.0</dynamic_bias_correlation_time>
              <precision>0.005</precision>
            </noise>
          </z>
        </linear_acceleration>
      </imu>
    </sensor>
  </gazebo>
  <!-- Controllers & systems -->
  <gazebo>
    <plugin filename="libgz-sim-diff-drive-system.so" name="gz::sim::systems::DiffDrive">
      <left_joint>front_left_wheel_joint</left_joint>
      <left_joint>rear_left_wheel_joint</left_joint>
      <right_joint>front_right_wheel_joint</right_joint>
      <right_joint>rear_right_wheel_joint</right_joint>
      <wheel_radius>0.1651</wheel_radius>
      <wheel_separation>0.5708</wheel_separation>
      <topic>cmd_vel</topic>
      <odom_topic>odom</odom_topic>
      <frame_id>odom</frame_id>
      <child_frame_id>base_link</child_frame_id>
      <max_linear_acceleration>3.0</max_linear_acceleration>
      <max_angular_acceleration>6.0</max_angular_acceleration>
      <min_velocity>-2.0</min_velocity>
      <max_velocity>2.0</max_velocity>
      <min_angular_velocity>-3.0</min_angular_velocity>
      <max_angular_velocity>3.0</max_angular_velocity>
      <odom_publish_frequency>50</odom_publish_frequency>
      <use_velocity_commands>true</use_velocity_commands>
    </plugin>
    <plugin filename="libgz-sim-joint-controller-system.so" name="gz::sim::systems::JointController">
      <joint_name>pan_gimbal_joint</joint_name>
      <use_force_commands>true</use_force_commands>
      <p_gain>0.4</p_gain>
      <i_gain>10</i_gain>
    </plugin>
    <plugin filename="libgz-sim-joint-controller-system.so" name="gz::sim::systems::JointController">
      <joint_name>tilt_gimbal_joint</joint_name>
      <use_force_commands>true</use_force_commands>
      <p_gain>0.4</p_gain>
      <i_gain>10</i_gain>
    </plugin>
    <plugin filename="libgz-sim-joint-state-publisher-system.so" name="gz::sim::systems::JointStatePublisher">
      <joint_name>front_left_wheel_joint</joint_name>
      <joint_name>front_right_wheel_joint</joint_name>
      <joint_name>rear_left_wheel_joint</joint_name>
      <joint_name>rear_right_wheel_joint</joint_name>
      <joint_name>pan_gimbal_joint</joint_name>
      <joint_name>tilt_gimbal_joint</joint_name>
    </plugin>
  </gazebo>
  <!-- Camera Front -->
  <link name="camera_front_link"/>
  <joint name="camera_front_joint" type="fixed">
    <parent link="base_link"/>
    <child link="camera_front_link"/>
    <origin rpy="0 0 0" xyz="0.468 0 0.360"/>
  </joint>
  <!-- Camera Down -->
  <link name="camera_down_link"/>
  <joint name="camera_down_joint" type="fixed">
    <parent link="base_link"/>
    <child link="camera_down_link"/>
    <origin rpy="0 0.5236 0" xyz="0.468 0 0.335"/>
  </joint>
  <!-- Front 3D Lidar -->
  <link name="front_laser_link"/>
  <joint name="front_laser_joint" type="fixed">
    <parent link="base_link"/>
    <child link="front_laser_link"/>
    <origin rpy="0 0 0" xyz="0.424 0 0.387"/>
  </joint>
  <!-- IMU -->
  <link name="imu_link"/>
  <joint name="imu_joint" type="fixed">
    <parent link="base_link"/>
    <child link="imu_link"/>
    <origin rpy="0 0 0" xyz="0 0 0"/>
  </joint>
  <!-- planar_lidar_joint -->
  <joint name="planar_lidar_joint" type="fixed">
    <parent link="base_link"/>
    <child link="planar_lidar_link"/>
    <origin rpy="0 0 0" xyz="0.474 0 0.127"/>
  </joint>
  <!-- Example for front_left_wheel_link -->
  <gazebo reference="front_left_wheel_link">
    <mu1>2.0</mu1>
    <mu2>2.0</mu2>
    <surface>
      <friction>
        <ode>
          <mu>2.0</mu>
          <mu2>2.0</mu2>
        </ode>
      </friction>
    </surface>
  </gazebo>
  <gazebo reference="front_right_wheel_link">
    <mu1>2.0</mu1>
    <mu2>2.0</mu2>
    <surface>
      <friction>
        <ode>
          <mu>2.0</mu>
          <mu2>2.0</mu2>
        </ode>
      </friction>
    </surface>
  </gazebo>
  <gazebo reference="rear_left_wheel_link">
    <mu1>2.0</mu1>
    <mu2>2.0</mu2>
    <surface>
      <friction>
        <ode>
          <mu>2.0</mu>
          <mu2>2.0</mu2>
        </ode>
      </friction>
    </surface>
  </gazebo>
  <gazebo reference="rear_right_wheel_link">
    <mu1>2.0</mu1>
    <mu2>2.0</mu2>
    <surface>
      <friction>
        <ode>
          <mu>2.0</mu>
          <mu2>2.0</mu2>
        </ode>
      </friction>
    </surface>
  </gazebo>
  <!-- Paths -->
  <!-- ================== LINKS ================== -->
  <link name="panda_link0">
    <inertial>
      <origin rpy="0 0 0" xyz="-0.025566 -2.87883e-05 0.057332"/>
      <mass value="2.814271300104062"/>
      <inertia ixx="0.0075390636364814695" ixy="-1.5053124574783335e-05" ixz="-0.0012144328835738973" iyy="0.010508017427382959" iyz="1.0434803501032979e-05" izz="0.009864933638708275"/>
    </inertial>
    <visual>
      <geometry>
        <mesh filename="package://husky_panda_description/husky_panda_model/panda_mounted_husky/panda_model_description/meshes/visual/link0.dae"/>
      </geometry>
    </visual>
    <collision>
      <geometry>
        <mesh filename="package://husky_panda_description/husky_panda_model/panda_mounted_husky/panda_model_description/meshes/collision/link0.stl"/>
      </geometry>
    </collision>
  </link>
  <link name="panda_link1">
    <inertial>
      <origin rpy="0 0 0" xyz="-3.72212e-09 -0.0324958 -0.0675818"/>
      <mass value="2.6433170427227215"/>
      <inertia ixx="0.017405076982879724" ixy="-8.687986369621078e-09" ixz="-1.6277819062920423e-08" iyy="0.015352077935781732" iyz="0.004510855959102245" izz="0.005987891663073857"/>
    </inertial>
    <visual>
      <geometry>
        <mesh filename="package://husky_panda_description/husky_panda_model/panda_mounted_husky/panda_model_description/meshes/visual/link1.dae"/>
      </geometry>
    </visual>
    <collision>
      <geometry>
        <mesh filename="package://husky_panda_description/husky_panda_model/panda_mounted_husky/panda_model_description/meshes/collision/link1.stl"/>
      </geometry>
    </collision>
  </link>
  <link name="panda_link2">
    <inertial>
      <origin rpy="0 0 0" xyz="3.17833e-07 -0.06861 0.0322285"/>
      <mass value="2.6652755331661186"/>
      <inertia ixx="0.01778694005635383" ixy="8.70635625879119e-08" ixz="3.752072058394008e-08" iyy="0.006044133867952844" iyz="-0.004599490295490376" izz="0.01571095500455695"/>
    </inertial>
    <visual>
      <geometry>
        <mesh filename="package://husky_panda_description/husky_panda_model/panda_mounted_husky/panda_model_description/meshes/visual/link2.dae"/>
      </geometry>
    </visual>
    <collision>
      <geometry>
        <mesh filename="package://husky_panda_description/husky_panda_model/panda_mounted_husky/panda_model_description/meshes/collision/link2.stl"/>
      </geometry>
    </collision>
  </link>
  <link name="panda_link3">
    <inertial>
      <origin rpy="0 0 0" xyz="0.0469893 0.0316374 -0.031704"/>
      <mass value="2.3293714829045733"/>
      <inertia ixx="0.0075496764161139766" ixy="-0.0024320464513492225" ixz="-0.003250815048103007" iyy="0.009680676080191398" iyz="-0.0021316282421730694" izz="0.007944557422008086"/>
    </inertial>
    <visual>
      <geometry>
        <mesh filename="package://husky_panda_description/husky_panda_model/panda_mounted_husky/panda_model_description/meshes/visual/link3.dae"/>
      </geometry>
    </visual>
    <collision>
      <geometry>
        <mesh filename="package://husky_panda_description/husky_panda_model/panda_mounted_husky/panda_model_description/meshes/collision/link3.stl"/>
      </geometry>
    </collision>
  </link>
  <link name="panda_link4">
    <inertial>
      <origin rpy="0 0 0" xyz="-0.0360505 0.0337069 0.0319019"/>
      <mass value="2.3104763646281508"/>
      <inertia ixx="0.007764568814864828" ixy="0.003371475204045935" ixz="-0.002343621113168248" iyy="0.008015776929980149" iyz="0.0022917526161470624" izz="0.009955882308071066"/>
    </inertial>
    <visual>
      <geometry>
        <mesh filename="package://husky_panda_description/husky_panda_model/panda_mounted_husky/panda_model_description/meshes/visual/link4.dae"/>
      </geometry>
    </visual>
    <collision>
      <geometry>
        <mesh filename="package://husky_panda_description/husky_panda_model/panda_mounted_husky/panda_model_description/meshes/collision/link4.stl"/>
      </geometry>
    </collision>
  </link>
  <link name="panda_link5">
    <inertial>
      <origin rpy="0 0 0" xyz="-6.12525e-06 0.0610427 -0.104176"/>
      <mass value="2.6226426154892004"/>
      <inertia ixx="0.029070538014399377" ixy="6.208738268725568e-07" ixz="-1.0059151925023392e-05" iyy="0.027638529986528795" iyz="-0.007424306477850814" izz="0.004251111234400737"/>
    </inertial>
    <visual>
      <geometry>
        <mesh filename="package://husky_panda_description/husky_panda_model/panda_mounted_husky/panda_model_description/meshes/visual/link5.dae"/>
      </geometry>
    </visual>
    <collision>
      <geometry>
        <mesh filename="package://husky_panda_description/husky_panda_model/panda_mounted_husky/panda_model_description/meshes/collision/link5.stl"/>
      </geometry>
    </collision>
  </link>
  <link name="panda_link6">
    <inertial>
      <origin rpy="0 0 0" xyz="0.051051 0.00910797 0.0106343"/>
      <mass value="1.5025804886626795"/>
      <inertia ixx="0.002940555801469018" ixy="-0.00042391108351381507" ixz="0.000610007735338717" iyy="0.00392105201248677" iyz="0.00012647545430836214" izz="0.0054115603870960195"/>
    </inertial>
    <visual>
      <geometry>
        <mesh filename="package://husky_panda_description/husky_panda_model/panda_mounted_husky/panda_model_description/meshes/visual/link6.dae"/>
      </geometry>
    </visual>
    <collision>
      <geometry>
        <mesh filename="package://husky_panda_description/husky_panda_model/panda_mounted_husky/panda_model_description/meshes/collision/link6.stl"/>
      </geometry>
    </collision>
  </link>
  <link name="panda_link7">
    <inertial>
      <origin rpy="0 0 0" xyz="0.0109695 0.0107965 0.0650412"/>
      <mass value="0.5237668134788256"/>
      <inertia ixx="0.0008621467959726535" ixy="-0.00011871071570425467" ixz="3.866602604509339e-05" iyy="0.0008613100184801048" iyz="-9.057841649422724e-05" izz="0.0006961139396618219"/>
    </inertial>
    <visual name="panda_link7_visual">
      <geometry>
        <mesh filename="package://husky_panda_description/husky_panda_model/panda_mounted_husky/panda_model_description/meshes/visual/link7.dae"/>
      </geometry>
    </visual>
    <collision name="panda_link7_collision">
      <geometry>
        <mesh filename="package://husky_panda_description/husky_panda_model/panda_mounted_husky/panda_model_description/meshes/collision/link7.stl"/>
      </geometry>
    </collision>
    <!-- Hand shell mounted on link7 (from SDF) -->
    <collision name="panda_hand_collision">
      <origin rpy="0 0 -0.7853981633974483" xyz="0 0 0.107"/>
      <geometry>
        <mesh filename="package://husky_panda_description/husky_panda_model/panda_mounted_husky/panda_model_description/meshes/collision/hand.stl" scale="1 1 1"/>
      </geometry>
    </collision>
    <visual name="panda_hand_visual">
      <origin rpy="0 0 -0.7853981633974483" xyz="0 0 0.107"/>
      <geometry>
        <mesh filename="package://husky_panda_description/husky_panda_model/panda_mounted_husky/panda_model_description/meshes/visual/hand.dae" scale="1 1 1"/>
      </geometry>
    </visual>
  </link>
  <!-- SDF frame as massless link -->
  <link name="wrist_mount"/>
  <!-- Camera body (small mass to keep physics stable) -->
  <link name="wrist_cam_link">
    <inertial>
      <mass value="0.08"/>
      <origin rpy="0 0 0" xyz="0 0 0"/>
      <inertia ixx="0.0001" ixy="0" ixz="0" iyy="0.0001" iyz="0" izz="0.0001"/>
    </inertial>
    <visual name="wrist_cam_debug">
      <geometry>
        <box size="0.06 0.02 0.02"/>
      </geometry>
    </visual>
  </link>
  <!-- REP 103 optical frame -->
  <link name="wrist_cam_optical_frame"/>
  <!-- Fingers -->
  <link name="panda_leftfinger">
    <inertial>
      <origin rpy="0 0 0" xyz="-6.2561e-06 0.00227781 -0.0277116"/>
      <mass value="0.2238453537819424"/>
      <inertia ixx="6.7480416736369505e-05" ixy="-4.1027443646025684e-09" ixz="1.8693673970152991e-08" iyy="6.6271892216413953e-05" iyz="1.19675484743908e-05" izz="1.550396267804825e-05"/>
    </inertial>
    <visual>
      <geometry>
        <mesh filename="package://husky_panda_description/husky_panda_model/panda_mounted_husky/panda_model_description/meshes/visual/finger.dae"/>
      </geometry>
    </visual>
    <collision>
      <geometry>
        <mesh filename="package://husky_panda_description/husky_panda_model/panda_mounted_husky/panda_model_description/meshes/collision/finger.stl"/>
      </geometry>
    </collision>
  </link>
  <link name="panda_rightfinger">
    <inertial>
      <origin rpy="0 0 3.141592653589793" xyz="-6.2561e-06 0.00227781 -0.0277116"/>
      <mass value="0.2238453537819424"/>
      <inertia ixx="6.7480416736369505e-05" ixy="-4.1027443646025684e-09" ixz="1.8693673970152991e-08" iyy="6.6271892216413953e-05" iyz="1.19675484743908e-05" izz="1.550396267804825e-05"/>
    </inertial>
    <visual>
      <origin rpy="0 0 3.141592653589793" xyz="0 0 0"/>
      <geometry>
        <mesh filename="package://husky_panda_description/husky_panda_model/panda_mounted_husky/panda_model_description/meshes/visual/finger.dae"/>
      </geometry>
    </visual>
    <collision>
      <origin rpy="0 0 3.141592653589793" xyz="0 0 0"/>
      <geometry>
        <mesh filename="package://husky_panda_description/husky_panda_model/panda_mounted_husky/panda_model_description/meshes/collision/finger.stl"/>
      </geometry>
    </collision>
  </link>
  <!-- ================== JOINTS ================== -->
  <!-- <link name="world"/>

  <joint name="world_to_panda" type="fixed">
    <parent link="world"/>
    <child  link="panda_link0"/>
    <origin xyz="0 0 0" rpy="0 0 0"/>
  </joint> -->
  <joint name="panda_joint1" type="revolute">
    <parent link="panda_link0"/>
    <child link="panda_link1"/>
    <origin rpy="0 0 0" xyz="0 0 0.333"/>
    <axis xyz="0 0 1"/>
    <limit effort="87" lower="-2.897246558310587" upper="2.897246558310587" velocity="2.617993877991494"/>
    <dynamics damping="21.75" friction="3.48"/>
  </joint>
  <joint name="panda_joint2" type="revolute">
    <parent link="panda_link1"/>
    <child link="panda_link2"/>
    <origin rpy="-1.570796326794897 0 0" xyz="0 0 0"/>
    <axis xyz="0 0 1"/>
    <limit effort="87" lower="-1.762782544514273" upper="1.762782544514273" velocity="2.617993877991494"/>
    <dynamics damping="21.75" friction="3.48"/>
  </joint>
  <joint name="panda_joint3" type="revolute">
    <parent link="panda_link2"/>
    <child link="panda_link3"/>
    <origin rpy="1.570796326794897 0 0" xyz="0 -0.316 0"/>
    <axis xyz="0 0 1"/>
    <limit effort="87" lower="-2.897246558310587" upper="2.897246558310587" velocity="2.617993877991494"/>
    <dynamics damping="21.75" friction="3.48"/>
  </joint>
  <joint name="panda_joint4" type="revolute">
    <parent link="panda_link3"/>
    <child link="panda_link4"/>
    <origin rpy="1.570796326794897 0 0" xyz="0.0825 0 0"/>
    <axis xyz="0 0 1"/>
    <limit effort="87" lower="-3.07177948351002" upper="-0.06981317007977318" velocity="2.617993877991494"/>
    <dynamics damping="21.75" friction="3.48"/>
  </joint>
  <joint name="panda_joint5" type="revolute">
    <parent link="panda_link4"/>
    <child link="panda_link5"/>
    <origin rpy="-1.570796326794897 0 0" xyz="-0.0825 0.384 0"/>
    <axis xyz="0 0 1"/>
    <limit effort="12" lower="-2.897246558310587" upper="2.897246558310587" velocity="3.141592653589793"/>
    <dynamics damping="3.0" friction="0.48"/>
  </joint>
  <joint name="panda_joint6" type="revolute">
    <parent link="panda_link5"/>
    <child link="panda_link6"/>
    <origin rpy="1.570796326794897 0 0" xyz="0 0 0"/>
    <axis xyz="0 0 1"/>
    <limit effort="12" lower="-0.0174532925199433" upper="3.752457891787809" velocity="3.141592653589793"/>
    <dynamics damping="3.0" friction="0.48"/>
  </joint>
  <joint name="panda_joint7" type="revolute">
    <parent link="panda_link6"/>
    <child link="panda_link7"/>
    <origin rpy="1.570796326794897 -0.8 0.0" xyz="0.088 0 0"/>
    <axis xyz="0 0 1"/>
    <limit effort="12" lower="-2.897246558310587" upper="2.897246558310587" velocity="3.141592653589793"/>
    <dynamics damping="3.0" friction="0.48"/>
  </joint>
  <!-- fixed frames -->
  <joint name="panda_wrist_mount" type="fixed">
    <parent link="panda_link7"/>
    <child link="wrist_mount"/>
    <origin rpy="0 0 -0.7853981633974483" xyz="0 0 0.107"/>
  </joint>
  <joint name="wrist_cam_mount" type="fixed">
    <parent link="wrist_mount"/>
    <child link="wrist_cam_link"/>
    <!-- SDF had +5 cm forward from wrist_mount -->
    <origin rpy="0 0 0" xyz="0 0 0.05"/>
  </joint>
  <joint name="wrist_cam_optical_joint" type="fixed">
    <parent link="wrist_cam_link"/>
    <child link="wrist_cam_optical_frame"/>
    <!-- Z forward, X right, Y down -->
    <origin rpy="-1.57079632679 0 -1.57079632679" xyz="0 0 0"/>
  </joint>
  <!-- Fingers (prismatic) -->
  <joint name="panda_finger_joint1" type="prismatic">
    <parent link="panda_link7"/>
    <child link="panda_leftfinger"/>
    <origin rpy="0 0 -0.7853981633974483" xyz="0 0 0.1654"/>
    <axis xyz="0 1 0"/>
    <limit effort="20" lower="0.0" upper="0.04" velocity="0.2"/>
    <dynamics damping="3.0" friction="0.4"/>
  </joint>
  <joint name="panda_finger_joint2" type="prismatic">
    <parent link="panda_link7"/>
    <child link="panda_rightfinger"/>
    <origin rpy="0 0 -0.7853981633974483" xyz="0 0 0.1654"/>
    <axis xyz="0 -1 0"/>
    <limit effort="20" lower="0.0" upper="0.04" velocity="0.2"/>
    <dynamics damping="3.0" friction="0.4"/>
  </joint>
  <!-- ================== ros2_control ================== -->
  <ros2_control name="GazeboSimSystem" type="system">
    <hardware>
      <plugin>gz_ros2_control/GazeboSimSystem</plugin>
    </hardware>
    <!-- Arm -->
    <joint name="panda_joint1">
      <command_interface name="position"/>
      <state_interface name="position"/>
      <state_interface name="velocity"/>
      <state_interface name="effort"/>
    </joint>
    <joint name="panda_joint2">
      <command_interface name="position"/>
      <state_interface name="position"/>
      <state_interface name="velocity"/>
      <state_interface name="effort"/>
    </joint>
    <joint name="panda_joint3">
      <command_interface name="position"/>
      <state_interface name="position"/>
      <state_interface name="velocity"/>
      <state_interface name="effort"/>
    </joint>
    <joint name="panda_joint4">
      <command_interface name="position"/>
      <state_interface name="position"/>
      <state_interface name="velocity"/>
      <state_interface name="effort"/>
    </joint>
    <joint name="panda_joint5">
      <command_interface name="position"/>
      <state_interface name="position"/>
      <state_interface name="velocity"/>
      <state_interface name="effort"/>
    </joint>
    <joint name="panda_joint6">
      <command_interface name="position"/>
      <state_interface name="position"/>
      <state_interface name="velocity"/>
      <state_interface name="effort"/>
    </joint>
    <joint name="panda_joint7">
      <command_interface name="position"/>
      <state_interface name="position"/>
      <state_interface name="velocity"/>
      <state_interface name="effort"/>
    </joint>
    <!-- wrist fingers -->
    <joint name="panda_finger_joint1">
      <command_interface name="position"/>
      <state_interface name="position"/>
      <state_interface name="velocity"/>
    </joint>
    <joint name="panda_finger_joint2">
      <command_interface name="position"/>
      <state_interface name="position"/>
      <state_interface name="velocity"/>
    </joint>
  </ros2_control>
  <!-- ================== Gazebo: load ros2_control, friction, and sensor ================== -->
  <!-- <gazebo>
    <plugin filename="libgz_ros2_control-system.so" name="gz_ros2_control::GazeboSimROS2ControlPlugin">
      <parameters>/config/controllers.yaml</parameters>
    </plugin>
  </gazebo> -->
  <gazebo reference="panda_link0">
    <gravity>false</gravity>
  </gazebo>
  <gazebo>
    <!-- J1 -->
    <plugin filename="libgz-sim-joint-position-controller-system.so" name="gz::sim::systems::JointPositionController">
      <joint_name>panda_joint1</joint_name>
      <p_gain>50</p_gain>
      <d_gain>20</d_gain>
      <i_gain>0</i_gain>
      <i_min>-1</i_min>
      <i_max>1</i_max>
      <cmd_min>-87</cmd_min>
      <cmd_max>87</cmd_max>
      <topic>/model/panda/joint/panda_joint1/cmd_pos</topic>
    </plugin>
    <!-- J2 -->
    <plugin filename="libgz-sim-joint-position-controller-system.so" name="gz::sim::systems::JointPositionController">
      <joint_name>panda_joint2</joint_name>
      <p_gain>10000</p_gain>
      <d_gain>500</d_gain>
      <i_gain>0</i_gain>
      <i_min>-1</i_min>
      <i_max>1</i_max>
      <cmd_min>-87</cmd_min>
      <cmd_max>87</cmd_max>
      <topic>/model/panda/joint/panda_joint2/cmd_pos</topic>
    </plugin>
    <!-- J3 -->
    <plugin filename="libgz-sim-joint-position-controller-system.so" name="gz::sim::systems::JointPositionController">
      <joint_name>panda_joint3</joint_name>
      <p_gain>100</p_gain>
      <d_gain>10</d_gain>
      <i_gain>0</i_gain>
      <i_min>-1</i_min>
      <i_max>1</i_max>
      <cmd_min>-87</cmd_min>
      <cmd_max>87</cmd_max>
      <topic>/model/panda/joint/panda_joint3/cmd_pos</topic>
    </plugin>
    <!-- J4 -->
    <plugin filename="libgz-sim-joint-position-controller-system.so" name="gz::sim::systems::JointPositionController">
      <joint_name>panda_joint4</joint_name>
      <p_gain>1000</p_gain>
      <d_gain>50</d_gain>
      <i_gain>0</i_gain>
      <i_min>-1</i_min>
      <i_max>1</i_max>
      <cmd_min>-87</cmd_min>
      <cmd_max>87</cmd_max>
      <topic>/model/panda/joint/panda_joint4/cmd_pos</topic>
    </plugin>
    <!-- J5 -->
    <plugin filename="libgz-sim-joint-position-controller-system.so" name="gz::sim::systems::JointPositionController">
      <joint_name>panda_joint5</joint_name>
      <p_gain>100</p_gain>
      <d_gain>50</d_gain>
      <i_gain>0</i_gain>
      <i_min>-1</i_min>
      <i_max>1</i_max>
      <cmd_min>-12</cmd_min>
      <cmd_max>12</cmd_max>
      <topic>/model/panda/joint/panda_joint5/cmd_pos</topic>
    </plugin>
    <!-- J6 -->
    <plugin filename="libgz-sim-joint-position-controller-system.so" name="gz::sim::systems::JointPositionController">
      <joint_name>panda_joint6</joint_name>
      <p_gain>100</p_gain>
      <d_gain>10</d_gain>
      <i_gain>0</i_gain>
      <i_min>-1</i_min>
      <i_max>1</i_max>
      <cmd_min>-12</cmd_min>
      <cmd_max>12</cmd_max>
      <topic>/model/panda/joint/panda_joint6/cmd_pos</topic>
    </plugin>
    <!-- J7 -->
    <plugin filename="libgz-sim-joint-position-controller-system.so" name="gz::sim::systems::JointPositionController">
      <joint_name>panda_joint7</joint_name>
      <p_gain>10</p_gain>
      <d_gain>0.1</d_gain>
      <i_gain>0.5</i_gain>
      <i_min>-1</i_min>
      <i_max>1</i_max>
      <cmd_min>-12</cmd_min>
      <cmd_max>12</cmd_max>
      <topic>/model/panda/joint/panda_joint7/cmd_pos</topic>
    </plugin>
    <!-- Fingers -->
    <plugin filename="libgz-sim-joint-position-controller-system.so" name="gz::sim::systems::JointPositionController">
      <joint_name>panda_finger_joint1</joint_name>
      <p_gain>100</p_gain>
      <d_gain>10</d_gain>
      <i_gain>0</i_gain>
      <i_min>-1</i_min>
      <i_max>1</i_max>
      <cmd_min>-40</cmd_min>
      <cmd_max>40</cmd_max>
      <topic>/model/panda/joint/panda_finger_joint1/cmd_pos</topic>
    </plugin>
    <plugin filename="libgz-sim-joint-position-controller-system.so" name="gz::sim::systems::JointPositionController">
      <joint_name>panda_finger_joint2</joint_name>
      <p_gain>100</p_gain>
      <d_gain>10</d_gain>
      <i_gain>0</i_gain>
      <i_min>-1</i_min>
      <i_max>1</i_max>
      <cmd_min>-40</cmd_min>
      <cmd_max>40</cmd_max>
      <topic>/model/panda/joint/panda_finger_joint2/cmd_pos</topic>
    </plugin>
    <!-- Publish all joint states from Gazebo -->
    <plugin filename="libgz-sim-joint-state-publisher-system.so" name="gz::sim::systems::JointStatePublisher">
      <joint_name>panda_joint1</joint_name>
      <joint_name>panda_joint2</joint_name>
      <joint_name>panda_joint3</joint_name>
      <joint_name>panda_joint4</joint_name>
      <joint_name>panda_joint5</joint_name>
      <joint_name>panda_joint6</joint_name>
      <joint_name>panda_joint7</joint_name>
      <joint_name>panda_finger_joint1</joint_name>
      <joint_name>panda_finger_joint2</joint_name>
      <!-- (topic parameter is optional; defaults are fine) -->
    </plugin>
  </gazebo>
  <!-- friction approximations from SDF -->
  <gazebo reference="panda_link0">
    <mu1>1.05</mu1>
    <mu2>1.05</mu2>
  </gazebo>
  <gazebo reference="panda_link1">
    <mu1>1.05</mu1>
    <mu2>1.05</mu2>
  </gazebo>
  <gazebo reference="panda_link2">
    <mu1>1.05</mu1>
    <mu2>1.05</mu2>
  </gazebo>
  <gazebo reference="panda_link3">
    <mu1>1.05</mu1>
    <mu2>1.05</mu2>
  </gazebo>
  <gazebo reference="panda_link4">
    <mu1>1.05</mu1>
    <mu2>1.05</mu2>
  </gazebo>
  <gazebo reference="panda_link5">
    <mu1>1.05</mu1>
    <mu2>1.05</mu2>
  </gazebo>
  <gazebo reference="panda_link6">
    <mu1>1.05</mu1>
    <mu2>1.05</mu2>
  </gazebo>
  <gazebo reference="panda_link7">
    <mu1>1.05</mu1>
    <mu2>1.05</mu2>
  </gazebo>
  <gazebo reference="panda_leftfinger">
    <mu1>1.13</mu1>
    <mu2>1.13</mu2>
  </gazebo>
  <gazebo reference="panda_rightfinger">
    <mu1>1.13</mu1>
    <mu2>1.13</mu2>
  </gazebo>
  <!-- Embed the RGB-D sensor (GZ Sim understands SDF inside <gazebo> in URDF) -->
  <gazebo reference="wrist_cam_link">
    <sensor name="wrist_rgbd" type="rgbd_camera">
      <pose>0.015 0 0 0 -1.57079632679 0</pose>
      <update_rate>30</update_rate>
      <always_on>true</always_on>
      <visualize>true</visualize>
      <topic>/panda/wrist/rgbd</topic>
      <camera>
        <horizontal_fov>1.0471975512</horizontal_fov>
        <image>
          <width>640</width>
          <height>480</height>
          <format>R8G8B8</format>
        </image>
        <clip>
          <near>0.10</near>
          <far>5.0</far>
        </clip>
      </camera>
    </sensor>
  </gazebo>
  <!-- keeps joints 'panda_joint1'.. etc. -->
  <!-- ONE rigid joint between them so URDF is a single tree -->
  <joint name="husky_to_panda" type="fixed">
    <parent link="base_link"/>
    <!-- Husky base -->
    <child link="panda_link0"/>
    <!-- Panda base link -->
    <origin rpy="0 0 0" xyz="0 0 0.2325"/>
  </joint>
</robot>
